Grabbing thread from lore.kernel.org/all/20251015145808.1112843-1-vsementsov@yandex-team.ru/t.mbox.gz
Checking for newer revisions
Grabbing search results from lore.kernel.org
Traceback (most recent call last):
  File "/usr/lib/python3/dist-packages/urllib3/response.py", line 710, in _error_catcher
    yield
  File "/usr/lib/python3/dist-packages/urllib3/response.py", line 1073, in read_chunked
    self._update_chunk_length()
  File "/usr/lib/python3/dist-packages/urllib3/response.py", line 1008, in _update_chunk_length
    raise InvalidChunkLength(self, line) from None
urllib3.exceptions.InvalidChunkLength: InvalidChunkLength(got length b'', 0 bytes read)

The above exception was the direct cause of the following exception:

Traceback (most recent call last):
  File "/usr/lib/python3/dist-packages/requests/models.py", line 816, in generate
    yield from self.raw.stream(chunk_size, decode_content=True)
  File "/usr/lib/python3/dist-packages/urllib3/response.py", line 933, in stream
    yield from self.read_chunked(amt, decode_content=decode_content)
  File "/usr/lib/python3/dist-packages/urllib3/response.py", line 1061, in read_chunked
    with self._error_catcher():
  File "/usr/lib/python3.12/contextlib.py", line 158, in __exit__
    self.gen.throw(value)
  File "/usr/lib/python3/dist-packages/urllib3/response.py", line 727, in _error_catcher
    raise ProtocolError(f"Connection broken: {e!r}", e) from e
urllib3.exceptions.ProtocolError: ("Connection broken: InvalidChunkLength(got length b'', 0 bytes read)", InvalidChunkLength(got length b'', 0 bytes read))

During handling of the above exception, another exception occurred:

Traceback (most recent call last):
  File "/usr/local/bin/b4", line 8, in <module>
    sys.exit(cmd())
             ^^^^^
  File "/usr/local/lib/python3.12/dist-packages/b4/command.py", line 417, in cmd
    cmdargs.func(cmdargs)
  File "/usr/local/lib/python3.12/dist-packages/b4/command.py", line 103, in cmd_shazam
    b4.mbox.main(cmdargs)
  File "/usr/local/lib/python3.12/dist-packages/b4/mbox.py", line 826, in main
    msgs = get_extra_series(msgs, direction=1, nocache=cmdargs.nocache)
           ^^^^^^^^^^^^^^^^^^^^^^^^^^^^^^^^^^^^^^^^^^^^^^^^^^^^^^^^^^^^
  File "/usr/local/lib/python3.12/dist-packages/b4/mbox.py", line 639, in get_extra_series
    q_msgs = b4.get_pi_search_results(q, nocache=nocache)
             ^^^^^^^^^^^^^^^^^^^^^^^^^^^^^^^^^^^^^^^^^^^^
  File "/usr/local/lib/python3.12/dist-packages/b4/__init__.py", line 3294, in get_pi_search_results
    resp = session.post(query_url, data='')
           ^^^^^^^^^^^^^^^^^^^^^^^^^^^^^^^^
  File "/usr/lib/python3/dist-packages/requests/sessions.py", line 637, in post
    return self.request("POST", url, data=data, json=json, **kwargs)
           ^^^^^^^^^^^^^^^^^^^^^^^^^^^^^^^^^^^^^^^^^^^^^^^^^^^^^^^^^
  File "/usr/lib/python3/dist-packages/requests/sessions.py", line 589, in request
    resp = self.send(prep, **send_kwargs)
           ^^^^^^^^^^^^^^^^^^^^^^^^^^^^^^
  File "/usr/lib/python3/dist-packages/requests/sessions.py", line 747, in send
    r.content
  File "/usr/lib/python3/dist-packages/requests/models.py", line 899, in content
    self._content = b"".join(self.iter_content(CONTENT_CHUNK_SIZE)) or b""
                    ^^^^^^^^^^^^^^^^^^^^^^^^^^^^^^^^^^^^^^^^^^^^^^^
  File "/usr/lib/python3/dist-packages/requests/models.py", line 818, in generate
    raise ChunkedEncodingError(e)
requests.exceptions.ChunkedEncodingError: ("Connection broken: InvalidChunkLength(got length b'', 0 bytes read)", InvalidChunkLength(got length b'', 0 bytes read))
